# 异常

**异常是个类**，通过异常类实例化异常对象而存在

```java
NullPoniterException npe = new NullPoniterException("空指针异常了");
```

## java中处理异常的两种方式

* 在方法声明的位置上，使用throws关键字，抛给上一级
* 使用try catch语句进行异常的捕捉

## 编译时异常和运行时异常

![](https://tva1.sinaimg.cn/large/007S8ZIlly1ggtst98czyj30oj1ee0wr.jpg)

*  粉红色的是受检查的异常(checked exceptions)，也可以称为编译时异常。其必须被  try{}catch语句块所捕获，或者在方法签名里通过throws子句声明。受检查的异常必须在编译时被捕捉处理，命名为 Checked  Exception 是因为**Java编译器要进行检查**，Java虚拟机也要进行检查，以确保这个规则得到遵守。

* 绿色的异常是运行时异常(runtime exceptions)，也可以称为运行时异常。需要程序员自己分析代码决定是否捕获和处理，比如  空指针，被0除... 

* 而声明为Error的，则属于严重错误，如系统崩溃、虚拟机错误、动态链接失败等，这些错误无法恢复或者不可能捕捉，将导致应用程序中断，Error不需要捕捉。

```java
public class Test {

    public static void main(String[] args) throws Exception{
//        try{
//            new Test().function();
//        }catch (Exception e){
//            e.printStackTrace();
//        }
        new Test().function();
    }

    public void function() throws IOException {
        System.out.println("hello");
    }
}
```

IOException是编译时异常，**必须需要调用方去catch或者向上throws**，否则编译是不能通过的，**这是由编译器决定的**，就算运行过程不会抛这个异常，也必须catch。如果是RuntimeException，那么就不一定需要catch，完全由程序员去判断。

## 异常

```java
public class Test {

    public static void main(String[] args){
        try {
            new Test().function();
        } catch (Exception e){
            System.out.println(e.hashCode());  // 621009875
        }
    }

    public void function() {
        NullPointerException npe = new NullPointerException("空指针异常了");
        System.out.println(npe.hashCode()); // 621009875
        throw npe;
    }
}
```

程序中的Exception e其实表示下游传过来的 NullPointerException对象，有点类似于Exception e=new NullPointerException("空指针异常了")

### 常用方法

* getMessage():获取异常信息

* printStackTrace():打印异常堆栈信息（另起一个线程打印，可能不是按代码顺序输出）

```java
public static void main(String[] args){
  NullPointerException npe = new NullPointerException("这是空指针异常");
  System.out.println(npe.getMessage());
  System.out.println("===============");
  npe.printStackTrace();
}
```

输出：

```java
这是空指针异常
===============
java.lang.NullPointerException: 这是空指针异常
	at Test.main(Test.java:10)
```

### finally

finally子句中的代码是在最后执行的，**并且是一定会执行的**

通常用在关闭流，关闭数据库连接等等

如果try或者catch中有return怎么办？**也会去执行finally子句的**

```java
public class Test {

    public static void main(String[] args){
        try{
            Integer i = 1/0;
        }catch (Exception e){
            e.printStackTrace();
            return;
        }finally {
            System.out.println("finally");
        }
    }
}
```

输出：

```
java.lang.ArithmeticException: / by zero
	at Test.main(Test.java:11)
finally
```

补偿：但如果把return换成System.exit(0)的话，就不执行finally了

示例：

```java
public class Test {
    public static void main(String[] args) {
        int result = m();
        System.out.println(result);
    }

    public static int m(){
        int i = 100;
        try{
            return i;
        }finally {
            i++;
        }
    }
}
```

结果是100。不能理解可以看反编译结果

### 补充

final：关键字，表示最终不变的

finalize()：是Object中的一个方法

finally：关键字，与try结合，在异常处理机制中使用

## 自定义异常类

java中怎么定义异常类？

* 首先编写一个类继承Exception（编译时异常）或者RuntimeException（运行时异常）
* 提供两个构造方法，一个无参，一个带String参数

```java
public class MyException extends RuntimeException{
  public MyException(){
  }
  
  public MyException(String s){
    super(s);
  }
}
```

## 异常与方法覆盖

**编译时异常**在子父类覆盖(方法重写)中的体现

1、子类在覆盖父类时，如果父类的方法抛出异常，那么子类的覆盖方法，只能抛出父类的异常 或 其子类异常

2、如果父类方法 抛出 多个异常，那么子类在覆盖 该方法时，只能抛出 父类 异常的子集

3、如果父类 或者 接口 方法 中没有抛出异常，那么 其子类在覆盖 方法 时，也不可以抛出异常，如果子类方法发生了异常，就必须自己进行try-catch处理，绝对不能抛。

```java
class Chinese extends People{

    @Override
    public void doOther() throws Exception{  // 只能抛出父类的异常 或 其子类异常
        System.out.println("do other");
    }
}


class People{

    public void doOther() throws IOException{}
}

```

